<error errorId="92944498-0d76-4734-857e-6e94d8afbdae" host="SF-D001" type="System.Data.SqlClient.SqlException" message="Transaction (Process ID 57) was deadlocked on lock resources with another process and has been chosen as the deadlock victim. Rerun the transaction." source=".Net SqlClient Data Provider" detail="System.Data.Entity.Core.EntityCommandExecutionException: An error occurred while reading from the store provider's data reader. See the inner exception for details. ---&gt; System.Data.SqlClient.SqlException: Transaction (Process ID 57) was deadlocked on lock resources with another process and has been chosen as the deadlock victim. Rerun the transaction.&#xD;&#xA;   at System.Data.SqlClient.SqlConnection.OnError(SqlException exception, Boolean breakConnection, Action`1 wrapCloseInAction)&#xD;&#xA;   at System.Data.SqlClient.TdsParser.ThrowExceptionAndWarning(TdsParserStateObject stateObj, Boolean callerHasConnectionLock, Boolean asyncClose)&#xD;&#xA;   at System.Data.SqlClient.TdsParser.TryRun(RunBehavior runBehavior, SqlCommand cmdHandler, SqlDataReader dataStream, BulkCopySimpleResultSet bulkCopyHandler, TdsParserStateObject stateObj, Boolean&amp; dataReady)&#xD;&#xA;   at System.Data.SqlClient.SqlDataReader.TryHasMoreRows(Boolean&amp; moreRows)&#xD;&#xA;   at System.Data.SqlClient.SqlDataReader.TryReadInternal(Boolean setTimeout, Boolean&amp; more)&#xD;&#xA;   at System.Data.SqlClient.SqlDataReader.&lt;&gt;c__DisplayClass189_0.&lt;ReadAsync&gt;b__0(Task t)&#xD;&#xA;   at System.Data.SqlClient.SqlDataReader.InvokeRetryable[T](Func`2 moreFunc, TaskCompletionSource`1 source, IDisposable objectToDispose)&#xD;&#xA;--- End of stack trace from previous location where exception was thrown ---&#xD;&#xA;   at System.Runtime.CompilerServices.TaskAwaiter.ThrowForNonSuccess(Task task)&#xD;&#xA;   at System.Runtime.CompilerServices.TaskAwaiter.HandleNonSuccessAndDebuggerNotification(Task task)&#xD;&#xA;   at System.Data.Entity.Core.Common.Internal.Materialization.Shaper`1.&lt;StoreReadAsync&gt;d__0.MoveNext()&#xD;&#xA;   --- End of inner exception stack trace ---&#xD;&#xA;   at System.Data.Entity.Core.Common.Internal.Materialization.Shaper`1.HandleReaderException(Exception e)&#xD;&#xA;   at System.Data.Entity.Core.Common.Internal.Materialization.Shaper`1.&lt;StoreReadAsync&gt;d__0.MoveNext()&#xD;&#xA;--- End of stack trace from previous location where exception was thrown ---&#xD;&#xA;   at System.Runtime.CompilerServices.TaskAwaiter.ThrowForNonSuccess(Task task)&#xD;&#xA;   at System.Runtime.CompilerServices.TaskAwaiter.HandleNonSuccessAndDebuggerNotification(Task task)&#xD;&#xA;   at System.Data.Entity.Core.Common.Internal.Materialization.Shaper`1.RowNestedResultEnumerator.&lt;MoveNextAsync&gt;d__7.MoveNext()&#xD;&#xA;--- End of stack trace from previous location where exception was thrown ---&#xD;&#xA;   at System.Runtime.CompilerServices.TaskAwaiter.ThrowForNonSuccess(Task task)&#xD;&#xA;   at System.Runtime.CompilerServices.TaskAwaiter.HandleNonSuccessAndDebuggerNotification(Task task)&#xD;&#xA;   at System.Data.Entity.Core.Common.Internal.Materialization.Shaper`1.ObjectQueryNestedEnumerator.&lt;TryReadToNextElementAsync&gt;d__12.MoveNext()&#xD;&#xA;--- End of stack trace from previous location where exception was thrown ---&#xD;&#xA;   at System.Runtime.CompilerServices.TaskAwaiter.ThrowForNonSuccess(Task task)&#xD;&#xA;   at System.Runtime.CompilerServices.TaskAwaiter.HandleNonSuccessAndDebuggerNotification(Task task)&#xD;&#xA;   at System.Data.Entity.Core.Common.Internal.Materialization.Shaper`1.ObjectQueryNestedEnumerator.&lt;MoveNextAsync&gt;d__a.MoveNext()&#xD;&#xA;--- End of stack trace from previous location where exception was thrown ---&#xD;&#xA;   at System.Runtime.CompilerServices.TaskAwaiter.ThrowForNonSuccess(Task task)&#xD;&#xA;   at System.Runtime.CompilerServices.TaskAwaiter.HandleNonSuccessAndDebuggerNotification(Task task)&#xD;&#xA;   at System.Data.Entity.Internal.LazyAsyncEnumerator`1.&lt;FirstMoveNextAsync&gt;d__0.MoveNext()&#xD;&#xA;--- End of stack trace from previous location where exception was thrown ---&#xD;&#xA;   at System.Runtime.CompilerServices.TaskAwaiter.ThrowForNonSuccess(Task task)&#xD;&#xA;   at System.Runtime.CompilerServices.TaskAwaiter.HandleNonSuccessAndDebuggerNotification(Task task)&#xD;&#xA;   at System.Data.Entity.Infrastructure.IDbAsyncEnumerableExtensions.&lt;ForEachAsync&gt;d__5`1.MoveNext()&#xD;&#xA;--- End of stack trace from previous location where exception was thrown ---&#xD;&#xA;   at System.Runtime.CompilerServices.TaskAwaiter.ThrowForNonSuccess(Task task)&#xD;&#xA;   at System.Runtime.CompilerServices.TaskAwaiter.HandleNonSuccessAndDebuggerNotification(Task task)&#xD;&#xA;   at System.Runtime.CompilerServices.TaskAwaiter`1.GetResult()&#xD;&#xA;   at CHM.Services.Controllers.InterventionsController.&lt;GetInterventionsForResident&gt;d__4.MoveNext() in E:\Enthusis_Latest\Enthusis.Services\CHM.Services\CHM.Services\Controllers\InterventionsController.cs:line 483&#xD;&#xA;--- End of stack trace from previous location where exception was thrown ---&#xD;&#xA;   at System.Runtime.CompilerServices.TaskAwaiter.ThrowForNonSuccess(Task task)&#xD;&#xA;   at System.Runtime.CompilerServices.TaskAwaiter.HandleNonSuccessAndDebuggerNotification(Task task)&#xD;&#xA;   at System.Threading.Tasks.TaskHelpersExtensions.&lt;CastToObject&gt;d__3`1.MoveNext()&#xD;&#xA;--- End of stack trace from previous location where exception was thrown ---&#xD;&#xA;   at System.Runtime.CompilerServices.TaskAwaiter.ThrowForNonSuccess(Task task)&#xD;&#xA;   at System.Runtime.CompilerServices.TaskAwaiter.HandleNonSuccessAndDebuggerNotification(Task task)&#xD;&#xA;   at System.Web.Http.Controllers.ApiControllerActionInvoker.&lt;InvokeActionAsyncCore&gt;d__0.MoveNext()&#xD;&#xA;--- End of stack trace from previous location where exception was thrown ---&#xD;&#xA;   at System.Runtime.CompilerServices.TaskAwaiter.ThrowForNonSuccess(Task task)&#xD;&#xA;   at System.Runtime.CompilerServices.TaskAwaiter.HandleNonSuccessAndDebuggerNotification(Task task)&#xD;&#xA;   at System.Web.Http.Controllers.ActionFilterResult.&lt;ExecuteAsync&gt;d__2.MoveNext()&#xD;&#xA;--- End of stack trace from previous location where exception was thrown ---&#xD;&#xA;   at System.Runtime.CompilerServices.TaskAwaiter.ThrowForNonSuccess(Task task)&#xD;&#xA;   at System.Runtime.CompilerServices.TaskAwaiter.HandleNonSuccessAndDebuggerNotification(Task task)&#xD;&#xA;   at System.Web.Http.Controllers.ExceptionFilterResult.&lt;ExecuteAsync&gt;d__0.MoveNext()" user="samathareddy216@gmail.com" time="2017-01-18T06:58:55.2285177Z" />